Workbook
Name IT1_処理結合テスト: マスタ!$B$3:$L$3
Name IT2_機能結合テスト: マスタ!$B$4:$L$4
Name IT3_業務結合テスト: マスタ!$B$5:$L$5
Name IT4_外部連携テスト: マスタ!$B$6:$L$6
Name ST_システムテスト: マスタ!$B$7:$L$7
Name UT_単体テスト: マスタ!$B$2:$L$2
Name エラー原因: #REF!
Name 凡例: '[1]画面一覧（サンプル）'!$A$30:$A$32

Sheet 変更履歴
B2: 試験項目書_Ne-OpS名整合性チェック
B3: <変更履歴>
B4: 版数 | E4: 日付 | I4: 変更者 | N4: 変更内容
B5: 1.00 | E5: 2026/5/28 | I5: 土橋 | N5: 2026C_L1EOL対応STEP3(JP5移設) 新規作成

Sheet 試験実施要領
A1: テストフェース | D1: ST_システムテスト
A2: テスト概要 | D2: 当該バッチの正常実行確認 新旧比較による性能（負荷）観点の確認
A3: テスト対象（機能/クラス） | D3: Ne-OpS名整合性チェック（CDDB2000）バッチ
A4: テストスコープ | C4: テスト対象要件① | D4: Ne-OpS名整合性チェック（CDDB2000）バッチの性能確認（新旧比較）
C5: テスト対象要件②
C6: テスト対象要件③
C7: 回帰確認① | D7: NeOps名が正しいルールでついていること
C8: 回帰確認②
C9: 回帰確認②
A10: スタブ・モック情報 | D10: なし
A18: テスト環境 | D18: 習熟環境
A19: 試験実施方法 | D19: シェル実行にて確認
A20: 試験項目レビューチェック
A21: No | B21: 大分類 | C21: 小分類 | D21: チェック内容 | E21: 対象 | F21: 記載者 | G21: 記載日 | H21: 確認者 | I21: 確認日
A22: 1 | B22: 実施要領 | C22: テスト対象 | D22: テスト対象に相違はないか？ | E22: ○ | F22: 土橋 | G22: 46171
A23: 2 | C23: テストスコープ | D23: テストを実施する要件や回帰テストに対する実施範囲に相違はないか？ | E23: ○ | F23: 土橋 | G23: 46171
A24: 3 | C24: スタブ・モック情報 | D24: スタブ・モック化する処理、機能に相違はないか？ | E24: - | F24: 土橋 | G24: 46171
A25: 4 | C25: テスト環境 | D25: テスト実施する環境に相違はないか？ | E25: ○ | F25: 土橋 | G25: 46171
A26: 5 | C26: 試験実施方法 | D26: 試験実施方法に相違はないか？ | E26: ○ | F26: 土橋 | G26: 46171
A27: 6 | B27: 入力 | C27: バリエーション | D27: 入力値に対するバリエーションはパターン表およびデシジョン表にて網羅されているか？ | E27: ○ | F27: 土橋 | G27: 46171
A28: 7 | C28: 特殊値 | D28: 特殊な値が試験項目に考慮されているか？ ・NULL、空文字、スペース、エスケープシーケンス（\t, \nなど）、機種依存文字、 日付フォーマット | E28: - | F28: 土橋 | G28: 46171
A29: 8 | C29: 環境依存 | D29: 環境依存に起因するテスト項目が網羅されているか？ | E29: - | F29: 土橋 | G29: 46171
A30: 9 | C30: 有無 | D30: 入力値の有無が試験項目に考慮されているか？ | E30: - | F30: 土橋 | G30: 46171
A31: 10 | B31: 処理/機能/業務 | C31: バリエーション | D31: テストする処理/機能/業務はパターン表およびディシジョン表にて網羅されているか？ | E31: ○ | F31: 土橋 | G31: 46171
A32: 11 | C32: チェック処理 | D32: ①チェック内容については設計書に記載されている内容が網羅されているか？ ②チェックに利用する値については境界、最大、最少が考慮されているか？ ③タイミングおよびメッセージorログについての確認も考慮されているか？ | E32: - | F32: 土橋 | G32: 46171
A33: 12 | C33: 制御処理（主にUT） | D33: ①ループ処理、条件分岐は境界、最大、最少が考慮されているか？ 例：ループ0回、1回、通常回数、最大回数、最大回数－1回のパターンを確認する ②例外処理も含めてた命令の網羅が考慮されているか？ | E33: - | F33: 土橋 | G33: 46171
A34: 13 | C34: 編集処理 | D34: 編集内容のバリエーションがパターン表およびディシジョン表にて網羅されているか？ | E34: - | F34: 土橋 | G34: 46171
A35: 14 | C35: 処理/機能/業務フロー | D35: ①処理フロー、機能フロー、業務フローがパターン表およびディシジョン表にて網羅されているか？ ②例外について網羅されているか？ | E35: - | F35: 土橋 | G35: 46171
A36: 15 | C36: トランザクション | D36: トランザクションの確認は網羅されているか？ | E36: - | F36: 土橋 | G36: 46171
A37: 16 | B37: 出力 | C37: バリエーション | D37: 各出力値のバリエーションはパターン表およびディシジョン表にて網羅されているか？ | E37: - | F37: 土橋 | G37: 46171
A38: 17 | C38: メッセージ/ログ | D38: ①出力されるメッセージ/ログは網羅的に確認されているか？ ②置換文字のパターンも含め網羅されているか？ | E38: - | F38: 土橋 | G38: 46171
A39: 18 | C39: レイアウト | D39: ①レイアウトの確認点が網羅されているか？ ・表示位置、配置、色、サイズ、フォント、フォーマット、カーソル位置、 タブ、スクロール位置、印刷サイズ ②各項目の表示・非表示の確認点が網羅されているか？ | E39: - | F39: 土橋 | G39: 46171
A40: 19 | C40: 状態遷移 | D40: 状態遷移に対するバリエーションがパターン表およびディシジョン表にて網羅されているか？ | E40: - | F40: 土橋 | G40: 46171
A41: 20 | C41: 画面遷移 | D41: 画面遷移のバリエーションがパターン表およびディシジョン表にて網羅されているか？ | E41: - | F41: 土橋 | G41: 46171
A42: 21 | B42: 性能 | C42: バリエーション | D42: 性能・負荷・ロードテストを実施する際のバリエーションは適切か？ | E42: - | F42: 土橋 | G42: 46171
A43: 22 | C43: データ量 | D43: 性能・負荷・ロードテストを実施する際のデータ量は適切か？ | E43: - | F43: 土橋 | G43: 46171
A44: 23 | C44: 指標値 | D44: 性能・負荷・ロードテストを実施する際の指標値は適切か？ | E44: 〇 | F44: 土橋 | G44: 46171

Sheet パターン表
F4: 正常終了 | G4: 異常終了
B5: パターンID | C5: パターン概要 | D5: 補足 | E5: テストケースID
B6: PT001-001 | C6: 正常終了 | E6: =IFERROR(IF(B6="","",INDEX([2]試験項目書!C14:C256,MATCH("*"&B6&"*",[2]試験項目書!U14:U256,0))),"") -> 1 | F6: 〇 | G6: -
E7: =IFERROR(IF(B7="","",INDEX(#REF!,MATCH("*"&B7&"*",#REF!,0))),"")

Sheet 試験項目書
B1: テストフェーズ | D1: =試験実施要領!D1 -> ST_システムテスト
B2: テストケース数 | D2: =SUM(G:G) -> 1
B3: テスト項目数 | D3: =SUM(Q:Q) -> 8
B4: テストケース数_実績 | D4: =COUNTIF(I13:I82,"<>")-COUNTBLANK(I13:I82) -> 0
B5: テスト項目数_実績 | D5: =SUMIF(AF13:AF82,"<>*",Q13:Q82) -> 8
B6: カバレッジ_C0
B7: カバレッジ_C1
R8: 入力値 | W8: 期待値 | AA8: 実施状況 | AJ8: クロスチェック | AS8: EOL
B9: No | C9: テスト ケース番号 | D9: =IF(D1="UT_単体テスト","テストコードとの紐付け","機能定義との紐付け") -> 機能定義との紐付け | E9: テストケース概要 | F9: テスト分類 | G9: テスト ケース 数 | H9: 開始日 | I9: 完了日 | J9: 項目 番号 | K9: 確認 番号 | L9: 修正対象 | M9: 確認項目概要 | N9: 入力 確認 | O9: 実施 要否 | P9: 理由 | Q9: 確認 項目 数 | R9: 画面ID | S9: イベント | T9: 前提条件・操作 | U9: ﾊﾟﾀｰﾝ表 | V9: ﾃﾞｨｼｼﾞｮﾝ 表 | W9: 確認機能 確認処理 | X9: 確認内容 | Y9: 別紙 確認項目 シート名 | Z9: 確認 項目数 | AA9: 実施日 | AB9: 実施者 | AC9: NG解消 確認日 | AD9: 再確認 実施者 | AE9: 結果 | AF9: 完了日 | AG9: 故障管理No | AH9: 故障管理No 完了日 | AI9: 備考 | AJ9: 実施日 | AK9: 実施者 | AL9: NG解消 確認日 | AM9: 再確認 実施者 | AN9: 結果 | AO9: 完了日 | AP9: 故障管理No | AQ9: 故障管理No 完了日 | AR9: 備考 | AS9: EOL
AS10: EOL
AS11: EOL
B12: プロセス/機能/クラス/メソッド： | AS12: EOL
B13: 1 | C13: ST-001 | E13: 正常確認（旧環境） | G13: =IF(AND(C12<>C13,C13<>""),IF(SUMIFS($Q$13:$Q$82,$C$13:$C$82,$C13)>=1,1,0),"") -> 1 | I13: =IF($G13=1,IF(SUMPRODUCT(MAX(($C$13:$C$82=$C13)*($K$13:$K$82)))=COUNTIF($C13:$C$82,C13)-COUNTBLANK(OFFSET($AF13,0,0,COUNTIF($C13:$C$82,$C13),1)),IF(MAX(OFFSET($AF13,0,0,COUNTIF($C13:$C$82,$C13),1))=0,"",MAX(OFFSET($AF13,0,0,COUNTIF($C13:$C$82,$C13),1))),""),"") | J13: =IF(C13=0,"",IF(C12=C13,SUMPRODUCT(MAX(($C$11:$C12=C13)*($J$11:$J12))+1),1)) -> 1 | K13: =IF(C13=0,0,IF(AND(OR(N13="入力・確認",N13="確認"),O13<>"不要"),IF(C12=C13,SUMPRODUCT(MAX(($C$12:$C12=C13)*($K$12:$K12))+1),1),0)) -> 0 | M13: Ne-OpS名の確認 | Q13: =IF(AND(OR(N13="入力・確認",N13="確認"),O13<>"不要"),Z13,0) -> 0 | R13: NWZC7600 | S13: ユニットパラメータ登録 | T13: 【前提】 ・Ne-OpS名が作成されている対象データを取得する 対象データ取得シート参照 【操作】 ・取得データのビル、フロア、群、架、物品コードでユニット検索 | X13: ・Ne-OpS名が生成されていること ・物品コード：5L530065のユニットが割付られていること | AA13: 46210 | AB13: 藤田健人 | AE13: NG | AO13: =IF(AN13="OK",IF(AL13<>"",AL13,AJ13),"") | AS13: EOL
B14: =IF(AND(C14<>"",C13<>C14),MAX($B$13:B13)+1,"") | C14: ST-001 | G14: =IF(AND(C13<>C14,C14<>""),IF(SUMIFS($Q$13:$Q$82,$C$13:$C$82,$C14)>=1,1,0),"") | H14: =IF($G14=1,IF(MIN(OFFSET($AA14,0,0,COUNTIF($C14:$C$82,$C14),1))=0,"",MIN(OFFSET($AA14,0,0,COUNTIF($C14:$C$82,$C14),1))),"") | I14: =IF($G14=1,IF(SUMPRODUCT(MAX(($C$13:$C$82=$C14)*($K$13:$K$82)))=COUNTIF($C14:$C$82,C14)-COUNTBLANK(OFFSET($AF14,0,0,COUNTIF($C14:$C$82,$C14),1)),IF(MAX(OFFSET($AF14,0,0,COUNTIF($C14:$C$82,$C14),1))=0,"",MAX(OFFSET($AF14,0,0,COUNTIF($C14:$C$82,$C14),1))),""),"") | J14: =IF(C14=0,"",IF(C13=C14,SUMPRODUCT(MAX(($C$11:$C13=C14)*($J$11:$J13))+1),1)) -> 2 | K14: =IF(C14=0,0,IF(AND(OR(N14="入力・確認",N14="確認"),O14<>"不要"),IF(C13=C14,SUMPRODUCT(MAX(($C$12:$C13=C14)*($K$12:$K13))+1),1),0)) -> 1 | M14: Ne-OpS名整合性チェックバッチ処理１回目 | N14: 確認 | Q14: =IF(AND(OR(N14="入力・確認",N14="確認"),O14<>"不要"),Z14,0) -> 2 | T14: ・Ne-OpS名整合性チェックバッチ実行 バッチ実行手順シート参照 ・JOBLOGにて正常終了を確認 JOBLOG.log： /home/l1db/log/bat ・all.logにてエラー内容が出ていないこと | X14: ・Ne-OpS名エラーログにレコードが登録されていないこと ・バッチ正常終了のログ出力がされていること | Z14: 2 | AA14: 46210 | AB14: 藤田健人 | AE14: OK | AO14: =IF(AN14="OK",IF(AL14<>"",AL14,AJ14),"") | AS14: EOL
B15: =IF(AND(C15<>"",C14<>C15),MAX($B$13:B14)+1,"") | C15: ST-001 | G15: =IF(AND(C14<>C15,C15<>""),IF(SUMIFS($Q$13:$Q$82,$C$13:$C$82,$C15)>=1,1,0),"") | H15: =IF($G15=1,IF(MIN(OFFSET($AA15,0,0,COUNTIF($C15:$C$82,$C15),1))=0,"",MIN(OFFSET($AA15,0,0,COUNTIF($C15:$C$82,$C15),1))),"") | I15: =IF($G15=1,IF(SUMPRODUCT(MAX(($C$13:$C$82=$C15)*($K$13:$K$82)))=COUNTIF($C15:$C$82,C15)-COUNTBLANK(OFFSET($AF15,0,0,COUNTIF($C15:$C$82,$C15),1)),IF(MAX(OFFSET($AF15,0,0,COUNTIF($C15:$C$82,$C15),1))=0,"",MAX(OFFSET($AF15,0,0,COUNTIF($C15:$C$82,$C15),1))),""),"") | J15: =IF(C15=0,"",IF(C14=C15,SUMPRODUCT(MAX(($C$11:$C14=C15)*($J$11:$J14))+1),1)) -> 3 | K15: =IF(C15=0,0,IF(AND(OR(N15="入力・確認",N15="確認"),O15<>"不要"),IF(C14=C15,SUMPRODUCT(MAX(($C$12:$C14=C15)*($K$12:$K14))+1),1),0)) -> 0 | M15: コマ名を変更する | N15: 入力 | Q15: =IF(AND(OR(N15="入力・確認",N15="確認"),O15<>"不要"),Z15,0) -> 0 | T15: ・コマ名をNGに変更する 確認用シートのコマ名変更データパッチを実行 | X15: コマ名がNGに変更されていること | AA15: 46210 | AB15: 藤田健人 | AE15: OK | AO15: =IF(AN15="OK",IF(AL15<>"",AL15,AJ15),"") | AS15: EOL
B16: =IF(AND(C16<>"",C15<>C16),MAX($B$13:B15)+1,"") | C16: ST-001 | G16: =IF(AND(C15<>C16,C16<>""),IF(SUMIFS($Q$13:$Q$82,$C$13:$C$82,$C16)>=1,1,0),"") | H16: =IF($G16=1,IF(MIN(OFFSET($AA16,0,0,COUNTIF($C16:$C$82,$C16),1))=0,"",MIN(OFFSET($AA16,0,0,COUNTIF($C16:$C$82,$C16),1))),"") | I16: =IF($G16=1,IF(SUMPRODUCT(MAX(($C$13:$C$82=$C16)*($K$13:$K$82)))=COUNTIF($C16:$C$82,C16)-COUNTBLANK(OFFSET($AF16,0,0,COUNTIF($C16:$C$82,$C16),1)),IF(MAX(OFFSET($AF16,0,0,COUNTIF($C16:$C$82,$C16),1))=0,"",MAX(OFFSET($AF16,0,0,COUNTIF($C16:$C$82,$C16),1))),""),"") | J16: =IF(C16=0,"",IF(C15=C16,SUMPRODUCT(MAX(($C$11:$C15=C16)*($J$11:$J15))+1),1)) -> 4 | K16: =IF(C16=0,0,IF(AND(OR(N16="入力・確認",N16="確認"),O16<>"不要"),IF(C15=C16,SUMPRODUCT(MAX(($C$12:$C15=C16)*($K$12:$K15))+1),1),0)) -> 2 | M16: Ne-OpS名整合性チェックバッチ処理２回目 | N16: 確認 | Q16: =IF(AND(OR(N16="入力・確認",N16="確認"),O16<>"不要"),Z16,0) -> 2 | T16: ・Ne-OpS名整合性チェックバッチ実行 ・JOBLOGにて警告を確認 JOBLOG.log： /home/l1db/log/bat ・TD_NE_OPS_CHECK_ELOG（Ne-OpS名チェックエラーログ）のレコードを取得 ・all.logにてエラー内容が出ていること | X16: ・Ne-OpS名エラーログにレコードが登録されていること ・整合性チェックエラーの機器情報がログ出力されていること ・バッチエラー（警告）のログが出力されていること | Z16: 2 | AA16: 46210 | AB16: 藤田健人 | AE16: OK | AO16: =IF(AN16="OK",IF(AL16<>"",AL16,AJ16),"") | AS16: EOL
B17: =IF(AND(C17<>"",C16<>C17),MAX($B$13:B16)+1,"") | C17: ST-001 | G17: =IF(AND(C16<>C17,C17<>""),IF(SUMIFS($Q$13:$Q$82,$C$13:$C$82,$C17)>=1,1,0),"") | H17: =IF($G17=1,IF(MIN(OFFSET($AA17,0,0,COUNTIF($C17:$C$82,$C17),1))=0,"",MIN(OFFSET($AA17,0,0,COUNTIF($C17:$C$82,$C17),1))),"") | I17: =IF($G17=1,IF(SUMPRODUCT(MAX(($C$13:$C$82=$C17)*($K$13:$K$82)))=COUNTIF($C17:$C$82,C17)-COUNTBLANK(OFFSET($AF17,0,0,COUNTIF($C17:$C$82,$C17),1)),IF(MAX(OFFSET($AF17,0,0,COUNTIF($C17:$C$82,$C17),1))=0,"",MAX(OFFSET($AF17,0,0,COUNTIF($C17:$C$82,$C17),1))),""),"") | J17: =IF(C17=0,"",IF(C16=C17,SUMPRODUCT(MAX(($C$11:$C16=C17)*($J$11:$J16))+1),1)) -> 5 | K17: =IF(C17=0,0,IF(AND(OR(N17="入力・確認",N17="確認"),O17<>"不要"),IF(C16=C17,SUMPRODUCT(MAX(($C$12:$C16=C17)*($K$12:$K16))+1),1),0)) -> 3 | M17: Ne-OpS名整合性チェックバッチ処理３回目 | N17: 確認 | Q17: =IF(AND(OR(N17="入力・確認",N17="確認"),O17<>"不要"),Z17,0) -> 2 | T17: ・Ne-OpS名整合性チェックバッチ実行 ・JOBLOGにて正常終了を確認 JOBLOG.log： /home/l1db/log/bat | X17: ・Ne-OpS名エラーログが更新されていないこと ・バッチ正常終了のログが出力されていること | Z17: 2 | AA17: 46210 | AB17: 藤田健人 | AE17: OK | AO17: =IF(AN17="OK",IF(AL17<>"",AL17,AJ17),"") | AS17: EOL
B18: =IF(AND(C18<>"",C17<>C18),MAX($B$13:B17)+1,"") | C18: ST-001 | G18: =IF(AND(C17<>C18,C18<>""),IF(SUMIFS($Q$13:$Q$82,$C$13:$C$82,$C18)>=1,1,0),"") | H18: =IF($G18=1,IF(MIN(OFFSET($AA18,0,0,COUNTIF($C18:$C$82,$C18),1))=0,"",MIN(OFFSET($AA18,0,0,COUNTIF($C18:$C$82,$C18),1))),"") | I18: =IF($G18=1,IF(SUMPRODUCT(MAX(($C$13:$C$82=$C18)*($K$13:$K$82)))=COUNTIF($C18:$C$82,C18)-COUNTBLANK(OFFSET($AF18,0,0,COUNTIF($C18:$C$82,$C18),1)),IF(MAX(OFFSET($AF18,0,0,COUNTIF($C18:$C$82,$C18),1))=0,"",MAX(OFFSET($AF18,0,0,COUNTIF($C18:$C$82,$C18),1))),""),"") | J18: =IF(C18=0,"",IF(C17=C18,SUMPRODUCT(MAX(($C$11:$C17=C18)*($J$11:$J17))+1),1)) -> 6 | K18: =IF(C18=0,0,IF(AND(OR(N18="入力・確認",N18="確認"),O18<>"不要"),IF(C17=C18,SUMPRODUCT(MAX(($C$12:$C17=C18)*($K$12:$K17))+1),1),0)) -> 0 | M18: コマ名修正 | N18: 入力 | Q18: =IF(AND(OR(N18="入力・確認",N18="確認"),O18<>"不要"),Z18,0) -> 0 | T18: ・コマ名をD02に修正する ・確認用シートのコマ名修正データパッチを実行 | X18: コマ名がD02に変更されていること | AA18: 46210 | AB18: 藤田健人 | AE18: OK | AO18: =IF(AN18="OK",IF(AL18<>"",AL18,AJ18),"")
B19: =IF(AND(C19<>"",C18<>C19),MAX($B$13:B18)+1,"") | C19: ST-001 | G19: =IF(AND(C18<>C19,C19<>""),IF(SUMIFS($Q$13:$Q$82,$C$13:$C$82,$C19)>=1,1,0),"") | H19: =IF($G19=1,IF(MIN(OFFSET($AA19,0,0,COUNTIF($C19:$C$82,$C19),1))=0,"",MIN(OFFSET($AA19,0,0,COUNTIF($C19:$C$82,$C19),1))),"") | I19: =IF($G19=1,IF(SUMPRODUCT(MAX(($C$13:$C$82=$C19)*($K$13:$K$82)))=COUNTIF($C19:$C$82,C19)-COUNTBLANK(OFFSET($AF19,0,0,COUNTIF($C19:$C$82,$C19),1)),IF(MAX(OFFSET($AF19,0,0,COUNTIF($C19:$C$82,$C19),1))=0,"",MAX(OFFSET($AF19,0,0,COUNTIF($C19:$C$82,$C19),1))),""),"") | J19: =IF(C19=0,"",IF(C18=C19,SUMPRODUCT(MAX(($C$11:$C18=C19)*($J$11:$J18))+1),1)) -> 7 | K19: =IF(C19=0,0,IF(AND(OR(N19="入力・確認",N19="確認"),O19<>"不要"),IF(C18=C19,SUMPRODUCT(MAX(($C$12:$C18=C19)*($K$12:$K18))+1),1),0)) -> 4 | M19: Ne-OpS名整合性チェックバッチ処理４回目 | N19: 確認 | Q19: =IF(AND(OR(N19="入力・確認",N19="確認"),O19<>"不要"),Z19,0) -> 2 | T19: ・Ne-OpS名整合性チェックバッチ実行 ・JOBLOGにて正常終了を確認 JOBLOG.log： /home/l1db/log/bat ・TD_NE_OPS_CHECK_ELOG（Ne-OpS名チェックエラーログ）のレコードを取得 ・all.logにてエラー内容が出ていないこと | X19: ・Ne-OpS名エラーログの状態区分が1（解消）に更新されていること ・バッチ正常終了のログが出力されていること | Z19: 2 | AA19: 46210 | AB19: 藤田健人 | AE19: OK | AO19: =IF(AN19="OK",IF(AL19<>"",AL19,AJ19),"")
B20: =IF(AND(C20<>"",C19<>C20),MAX($B$13:B19)+1,"") -> 2 | C20: ST-002 | E20: 正常確認（新環境） | G20: =IF(AND(C19<>C20,C20<>""),IF(SUMIFS($Q$13:$Q$82,$C$13:$C$82,$C20)>=1,1,0),"") -> 0 | H20: =IF($G20=1,IF(MIN(OFFSET($AA20,0,0,COUNTIF($C20:$C$82,$C20),1))=0,"",MIN(OFFSET($AA20,0,0,COUNTIF($C20:$C$82,$C20),1))),"") | I20: =IF($G20=1,IF(SUMPRODUCT(MAX(($C$13:$C$82=$C20)*($K$13:$K$82)))=COUNTIF($C20:$C$82,C20)-COUNTBLANK(OFFSET($AF20,0,0,COUNTIF($C20:$C$82,$C20),1)),IF(MAX(OFFSET($AF20,0,0,COUNTIF($C20:$C$82,$C20),1))=0,"",MAX(OFFSET($AF20,0,0,COUNTIF($C20:$C$82,$C20),1))),""),"") | J20: =IF(C20=0,"",IF(C19=C20,SUMPRODUCT(MAX(($C$11:$C19=C20)*($J$11:$J19))+1),1)) -> 1 | K20: =IF(C20=0,0,IF(AND(OR(N20="入力・確認",N20="確認"),O20<>"不要"),IF(C19=C20,SUMPRODUCT(MAX(($C$12:$C19=C20)*($K$12:$K19))+1),1),0)) -> 1 | M20: Ne-OpS名の確認 | N20: 確認 | Q20: =IF(AND(OR(N20="入力・確認",N20="確認"),O20<>"不要"),Z20,0) -> 0 | R20: NWZC7600 | S20: ユニットパラメータ登録 | T20: 【前提】 ・Ne-OpS名が作成されている対象データを取得する 対象データ取得シート参照 【操作】 ・取得データのビル、フロア、群、架、物品コードでユニット検索 | X20: ・Ne-OpS名が生成されていること ・物品コード：5L530065のユニットが割付られていること | AO20: =IF(AN20="OK",IF(AL20<>"",AL20,AJ20),"")
B21: =IF(AND(C21<>"",C20<>C21),MAX($B$13:B20)+1,"") | C21: ST-002 | G21: =IF(AND(C20<>C21,C21<>""),IF(SUMIFS($Q$13:$Q$82,$C$13:$C$82,$C21)>=1,1,0),"") | H21: =IF($G21=1,IF(MIN(OFFSET($AA21,0,0,COUNTIF($C21:$C$82,$C21),1))=0,"",MIN(OFFSET($AA21,0,0,COUNTIF($C21:$C$82,$C21),1))),"") | I21: =IF($G21=1,IF(SUMPRODUCT(MAX(($C$13:$C$82=$C21)*($K$13:$K$82)))=COUNTIF($C21:$C$82,C21)-COUNTBLANK(OFFSET($AF21,0,0,COUNTIF($C21:$C$82,$C21),1)),IF(MAX(OFFSET($AF21,0,0,COUNTIF($C21:$C$82,$C21),1))=0,"",MAX(OFFSET($AF21,0,0,COUNTIF($C21:$C$82,$C21),1))),""),"") | J21: =IF(C21=0,"",IF(C20=C21,SUMPRODUCT(MAX(($C$11:$C20=C21)*($J$11:$J20))+1),1)) -> 2 | K21: =IF(C21=0,0,IF(AND(OR(N21="入力・確認",N21="確認"),O21<>"不要"),IF(C20=C21,SUMPRODUCT(MAX(($C$12:$C20=C21)*($K$12:$K20))+1),1),0)) -> 0 | M21: Ne-OpS名整合性チェックバッチ処理１回目 | Q21: =IF(AND(OR(N21="入力・確認",N21="確認"),O21<>"不要"),Z21,0) -> 0 | T21: ・Ne-OpS名整合性チェックバッチ実行 バッチ実行手順シート参照 ・JOBLOGにて正常終了を確認 JOBLOG.log： /home/l1db/log/bat ・all.logにてエラー内容が出ていないこと | X21: ・Ne-OpS名エラーログにレコードが登録されていないこと ・バッチ正常終了のログ出力がされていること | Z21: 2 | AO21: =IF(AN21="OK",IF(AL21<>"",AL21,AJ21),"")
B22: =IF(AND(C22<>"",C21<>C22),MAX($B$13:B21)+1,"") | C22: ST-002 | G22: =IF(AND(C21<>C22,C22<>""),IF(SUMIFS($Q$13:$Q$82,$C$13:$C$82,$C22)>=1,1,0),"") | H22: =IF($G22=1,IF(MIN(OFFSET($AA22,0,0,COUNTIF($C22:$C$82,$C22),1))=0,"",MIN(OFFSET($AA22,0,0,COUNTIF($C22:$C$82,$C22),1))),"") | I22: =IF($G22=1,IF(SUMPRODUCT(MAX(($C$13:$C$82=$C22)*($K$13:$K$82)))=COUNTIF($C22:$C$82,C22)-COUNTBLANK(OFFSET($AF22,0,0,COUNTIF($C22:$C$82,$C22),1)),IF(MAX(OFFSET($AF22,0,0,COUNTIF($C22:$C$82,$C22),1))=0,"",MAX(OFFSET($AF22,0,0,COUNTIF($C22:$C$82,$C22),1))),""),"") | J22: =IF(C22=0,"",IF(C21=C22,SUMPRODUCT(MAX(($C$11:$C21=C22)*($J$11:$J21))+1),1)) -> 3 | K22: =IF(C22=0,0,IF(AND(OR(N22="入力・確認",N22="確認"),O22<>"不要"),IF(C21=C22,SUMPRODUCT(MAX(($C$12:$C21=C22)*($K$12:$K21))+1),1),0)) -> 0 | M22: コマ名を変更する | Q22: =IF(AND(OR(N22="入力・確認",N22="確認"),O22<>"不要"),Z22,0) -> 0 | T22: ・コマ名をNGに変更する 確認用シートのコマ名変更データパッチを実行 | X22: コマ名がNGに変更されていること | AO22: =IF(AN22="OK",IF(AL22<>"",AL22,AJ22),"")
B23: =IF(AND(C23<>"",C22<>C23),MAX($B$13:B22)+1,"") | C23: ST-002 | G23: =IF(AND(C22<>C23,C23<>""),IF(SUMIFS($Q$13:$Q$82,$C$13:$C$82,$C23)>=1,1,0),"") | H23: =IF($G23=1,IF(MIN(OFFSET($AA23,0,0,COUNTIF($C23:$C$82,$C23),1))=0,"",MIN(OFFSET($AA23,0,0,COUNTIF($C23:$C$82,$C23),1))),"") | I23: =IF($G23=1,IF(SUMPRODUCT(MAX(($C$13:$C$82=$C23)*($K$13:$K$82)))=COUNTIF($C23:$C$82,C23)-COUNTBLANK(OFFSET($AF23,0,0,COUNTIF($C23:$C$82,$C23),1)),IF(MAX(OFFSET($AF23,0,0,COUNTIF($C23:$C$82,$C23),1))=0,"",MAX(OFFSET($AF23,0,0,COUNTIF($C23:$C$82,$C23),1))),""),"") | J23: =IF(C23=0,"",IF(C22=C23,SUMPRODUCT(MAX(($C$11:$C22=C23)*($J$11:$J22))+1),1)) -> 4 | K23: =IF(C23=0,0,IF(AND(OR(N23="入力・確認",N23="確認"),O23<>"不要"),IF(C22=C23,SUMPRODUCT(MAX(($C$12:$C22=C23)*($K$12:$K22))+1),1),0)) -> 0 | M23: Ne-OpS名整合性チェックバッチ処理２回目 | Q23: =IF(AND(OR(N23="入力・確認",N23="確認"),O23<>"不要"),Z23,0) -> 0 | T23: ・Ne-OpS名整合性チェックバッチ実行 ・JOBLOGにて警告を確認 JOBLOG.log： /home/l1db/log/bat ・TD_NE_OPS_CHECK_ELOG（Ne-OpS名チェックエラーログ）のレコードを取得 ・all.logにてエラー内容が出ていること | X23: ・Ne-OpS名エラーログにレコードが登録されていること ・整合性チェックエラーの機器情報がログ出力されていること ・バッチエラー（警告）のログが出力されていること | Z23: 2 | AO23: =IF(AN23="OK",IF(AL23<>"",AL23,AJ23),"")
B24: =IF(AND(C24<>"",C23<>C24),MAX($B$13:B23)+1,"") | C24: ST-002 | G24: =IF(AND(C23<>C24,C24<>""),IF(SUMIFS($Q$13:$Q$82,$C$13:$C$82,$C24)>=1,1,0),"") | H24: =IF($G24=1,IF(MIN(OFFSET($AA24,0,0,COUNTIF($C24:$C$82,$C24),1))=0,"",MIN(OFFSET($AA24,0,0,COUNTIF($C24:$C$82,$C24),1))),"") | I24: =IF($G24=1,IF(SUMPRODUCT(MAX(($C$13:$C$82=$C24)*($K$13:$K$82)))=COUNTIF($C24:$C$82,C24)-COUNTBLANK(OFFSET($AF24,0,0,COUNTIF($C24:$C$82,$C24),1)),IF(MAX(OFFSET($AF24,0,0,COUNTIF($C24:$C$82,$C24),1))=0,"",MAX(OFFSET($AF24,0,0,COUNTIF($C24:$C$82,$C24),1))),""),"") | J24: =IF(C24=0,"",IF(C23=C24,SUMPRODUCT(MAX(($C$11:$C23=C24)*($J$11:$J23))+1),1)) -> 5 | K24: =IF(C24=0,0,IF(AND(OR(N24="入力・確認",N24="確認"),O24<>"不要"),IF(C23=C24,SUMPRODUCT(MAX(($C$12:$C23=C24)*($K$12:$K23))+1),1),0)) -> 0 | M24: Ne-OpS名整合性チェックバッチ処理３回目 | Q24: =IF(AND(OR(N24="入力・確認",N24="確認"),O24<>"不要"),Z24,0) -> 0 | T24: ・Ne-OpS名整合性チェックバッチ実行 ・JOBLOGにて正常終了を確認 JOBLOG.log： /home/l1db/log/bat | X24: ・Ne-OpS名エラーログが更新されていないこと ・バッチ正常終了のログが出力されていること | Z24: 2 | AO24: =IF(AN24="OK",IF(AL24<>"",AL24,AJ24),"")
B25: =IF(AND(C25<>"",C24<>C25),MAX($B$13:B24)+1,"") | C25: ST-002 | G25: =IF(AND(C24<>C25,C25<>""),IF(SUMIFS($Q$13:$Q$82,$C$13:$C$82,$C25)>=1,1,0),"") | H25: =IF($G25=1,IF(MIN(OFFSET($AA25,0,0,COUNTIF($C25:$C$82,$C25),1))=0,"",MIN(OFFSET($AA25,0,0,COUNTIF($C25:$C$82,$C25),1))),"") | I25: =IF($G25=1,IF(SUMPRODUCT(MAX(($C$13:$C$82=$C25)*($K$13:$K$82)))=COUNTIF($C25:$C$82,C25)-COUNTBLANK(OFFSET($AF25,0,0,COUNTIF($C25:$C$82,$C25),1)),IF(MAX(OFFSET($AF25,0,0,COUNTIF($C25:$C$82,$C25),1))=0,"",MAX(OFFSET($AF25,0,0,COUNTIF($C25:$C$82,$C25),1))),""),"") | J25: =IF(C25=0,"",IF(C24=C25,SUMPRODUCT(MAX(($C$11:$C24=C25)*($J$11:$J24))+1),1)) -> 6 | K25: =IF(C25=0,0,IF(AND(OR(N25="入力・確認",N25="確認"),O25<>"不要"),IF(C24=C25,SUMPRODUCT(MAX(($C$12:$C24=C25)*($K$12:$K24))+1),1),0)) -> 0 | M25: コマ名修正 | Q25: =IF(AND(OR(N25="入力・確認",N25="確認"),O25<>"不要"),Z25,0) -> 0 | T25: ・コマ名をD02に修正する ・確認用シートのコマ名修正データパッチを実行 | X25: コマ名がD02に変更されていること | AO25: =IF(AN25="OK",IF(AL25<>"",AL25,AJ25),"")
B26: =IF(AND(C26<>"",C25<>C26),MAX($B$13:B25)+1,"") | C26: ST-002 | G26: =IF(AND(C25<>C26,C26<>""),IF(SUMIFS($Q$13:$Q$82,$C$13:$C$82,$C26)>=1,1,0),"") | H26: =IF($G26=1,IF(MIN(OFFSET($AA26,0,0,COUNTIF($C26:$C$82,$C26),1))=0,"",MIN(OFFSET($AA26,0,0,COUNTIF($C26:$C$82,$C26),1))),"") | I26: =IF($G26=1,IF(SUMPRODUCT(MAX(($C$13:$C$82=$C26)*($K$13:$K$82)))=COUNTIF($C26:$C$82,C26)-COUNTBLANK(OFFSET($AF26,0,0,COUNTIF($C26:$C$82,$C26),1)),IF(MAX(OFFSET($AF26,0,0,COUNTIF($C26:$C$82,$C26),1))=0,"",MAX(OFFSET($AF26,0,0,COUNTIF($C26:$C$82,$C26),1))),""),"") | J26: =IF(C26=0,"",IF(C25=C26,SUMPRODUCT(MAX(($C$11:$C25=C26)*($J$11:$J25))+1),1)) -> 7 | K26: =IF(C26=0,0,IF(AND(OR(N26="入力・確認",N26="確認"),O26<>"不要"),IF(C25=C26,SUMPRODUCT(MAX(($C$12:$C25=C26)*($K$12:$K25))+1),1),0)) -> 0 | M26: Ne-OpS名整合性チェックバッチ処理４回目 | Q26: =IF(AND(OR(N26="入力・確認",N26="確認"),O26<>"不要"),Z26,0) -> 0 | T26: ・Ne-OpS名整合性チェックバッチ実行 ・JOBLOGにて正常終了を確認 JOBLOG.log： /home/l1db/log/bat ・TD_NE_OPS_CHECK_ELOG（Ne-OpS名チェックエラーログ）のレコードを取得 ・all.logにてエラー内容が出ていないこと | X26: ・Ne-OpS名エラーログの状態区分が1（解消）に更新されていること ・バッチ正常終了のログが出力されていること | Z26: 2 | AO26: =IF(AN26="OK",IF(AL26<>"",AL26,AJ26),"")
B27: =IF(AND(C27<>"",C26<>C27),MAX($B$13:B26)+1,"") -> 3 | C27: ST-003 | E27: 性能試験 | G27: =IF(AND(C26<>C27,C27<>""),IF(SUMIFS($Q$13:$Q$82,$C$13:$C$82,$C27)>=1,1,0),"") -> 0 | H27: =IF($G27=1,IF(MIN(OFFSET($AA27,0,0,COUNTIF($C27:$C$82,$C27),1))=0,"",MIN(OFFSET($AA27,0,0,COUNTIF($C27:$C$82,$C27),1))),"") | I27: =IF($G27=1,IF(SUMPRODUCT(MAX(($C$13:$C$82=$C27)*($K$13:$K$82)))=COUNTIF($C27:$C$82,C27)-COUNTBLANK(OFFSET($AF27,0,0,COUNTIF($C27:$C$82,$C27),1)),IF(MAX(OFFSET($AF27,0,0,COUNTIF($C27:$C$82,$C27),1))=0,"",MAX(OFFSET($AF27,0,0,COUNTIF($C27:$C$82,$C27),1))),""),"") | J27: =IF(C27=0,"",IF(C26=C27,SUMPRODUCT(MAX(($C$11:$C26=C27)*($J$11:$J26))+1),1)) -> 1 | K27: =IF(C27=0,0,IF(AND(OR(N27="入力・確認",N27="確認"),O27<>"不要"),IF(C26=C27,SUMPRODUCT(MAX(($C$12:$C26=C27)*($K$12:$K26))+1),1),0)) -> 0 | M27: 旧環境と新環境で大きな差分がないこと | Q27: =IF(AND(OR(N27="入力・確認",N27="確認"),O27<>"不要"),Z27,0) -> 0 | T27: No1（移行前環境）とNo2（移行後環境）の実施時のログを比較する | X27: JOBLOG、All.logで大幅な差分がないこと （処理時間が新環境の方が早くなっている場合は問題なし。 遅くなっている場合は原因分析、再実行した上での妥当な差分であれば問題なし） | Z27: 1 | AF27: =IF(AE27="OK",IF(AC27<>"",AC27,AA27),"") | AO27: =IF(AN27="OK",IF(AL27<>"",AL27,AJ27),"")
B28: =IF(AND(C28<>"",C27<>C28),MAX($B$13:B27)+1,"") | G28: =IF(AND(C27<>C28,C28<>""),IF(SUMIFS($Q$13:$Q$82,$C$13:$C$82,$C28)>=1,1,0),"") | H28: =IF($G28=1,IF(MIN(OFFSET($AA28,0,0,COUNTIF($C28:$C$82,$C28),1))=0,"",MIN(OFFSET($AA28,0,0,COUNTIF($C28:$C$82,$C28),1))),"") | I28: =IF($G28=1,IF(SUMPRODUCT(MAX(($C$13:$C$82=$C28)*($K$13:$K$82)))=COUNTIF($C28:$C$82,C28)-COUNTBLANK(OFFSET($AF28,0,0,COUNTIF($C28:$C$82,$C28),1)),IF(MAX(OFFSET($AF28,0,0,COUNTIF($C28:$C$82,$C28),1))=0,"",MAX(OFFSET($AF28,0,0,COUNTIF($C28:$C$82,$C28),1))),""),"") | J28: =IF(C28=0,"",IF(C27=C28,SUMPRODUCT(MAX(($C$11:$C27=C28)*($J$11:$J27))+1),1)) | K28: =IF(C28=0,0,IF(AND(OR(N28="入力・確認",N28="確認"),O28<>"不要"),IF(C27=C28,SUMPRODUCT(MAX(($C$12:$C27=C28)*($K$12:$K27))+1),1),0)) -> 0 | Q28: =IF(AND(OR(N28="入力・確認",N28="確認"),O28<>"不要"),Z28,0) -> 0 | AF28: =IF(AE28="OK",IF(AC28<>"",AC28,AA28),"") | AO28: =IF(AN28="OK",IF(AL28<>"",AL28,AJ28),"")
B29: =IF(AND(C29<>"",C28<>C29),MAX($B$13:B28)+1,"") | G29: =IF(AND(C28<>C29,C29<>""),IF(SUMIFS($Q$13:$Q$82,$C$13:$C$82,$C29)>=1,1,0),"") | H29: =IF($G29=1,IF(MIN(OFFSET($AA29,0,0,COUNTIF($C29:$C$82,$C29),1))=0,"",MIN(OFFSET($AA29,0,0,COUNTIF($C29:$C$82,$C29),1))),"") | I29: =IF($G29=1,IF(SUMPRODUCT(MAX(($C$13:$C$82=$C29)*($K$13:$K$82)))=COUNTIF($C29:$C$82,C29)-COUNTBLANK(OFFSET($AF29,0,0,COUNTIF($C29:$C$82,$C29),1)),IF(MAX(OFFSET($AF29,0,0,COUNTIF($C29:$C$82,$C29),1))=0,"",MAX(OFFSET($AF29,0,0,COUNTIF($C29:$C$82,$C29),1))),""),"") | J29: =IF(C29=0,"",IF(C28=C29,SUMPRODUCT(MAX(($C$11:$C28=C29)*($J$11:$J28))+1),1)) | K29: =IF(C29=0,0,IF(AND(OR(N29="入力・確認",N29="確認"),O29<>"不要"),IF(C28=C29,SUMPRODUCT(MAX(($C$12:$C28=C29)*($K$12:$K28))+1),1),0)) -> 0 | Q29: =IF(AND(OR(N29="入力・確認",N29="確認"),O29<>"不要"),Z29,0) -> 0 | AF29: =IF(AE29="OK",IF(AC29<>"",AC29,AA29),"") | AO29: =IF(AN29="OK",IF(AL29<>"",AL29,AJ29),"")
B30: =IF(AND(C30<>"",C29<>C30),MAX($B$13:B29)+1,"") | G30: =IF(AND(C29<>C30,C30<>""),IF(SUMIFS($Q$13:$Q$82,$C$13:$C$82,$C30)>=1,1,0),"") | H30: =IF($G30=1,IF(MIN(OFFSET($AA30,0,0,COUNTIF($C30:$C$82,$C30),1))=0,"",MIN(OFFSET($AA30,0,0,COUNTIF($C30:$C$82,$C30),1))),"") | I30: =IF($G30=1,IF(SUMPRODUCT(MAX(($C$13:$C$82=$C30)*($K$13:$K$82)))=COUNTIF($C30:$C$82,C30)-COUNTBLANK(OFFSET($AF30,0,0,COUNTIF($C30:$C$82,$C30),1)),IF(MAX(OFFSET($AF30,0,0,COUNTIF($C30:$C$82,$C30),1))=0,"",MAX(OFFSET($AF30,0,0,COUNTIF($C30:$C$82,$C30),1))),""),"") | J30: =IF(C30=0,"",IF(C29=C30,SUMPRODUCT(MAX(($C$11:$C29=C30)*($J$11:$J29))+1),1)) | K30: =IF(C30=0,0,IF(AND(OR(N30="入力・確認",N30="確認"),O30<>"不要"),IF(C29=C30,SUMPRODUCT(MAX(($C$12:$C29=C30)*($K$12:$K29))+1),1),0)) -> 0 | Q30: =IF(AND(OR(N30="入力・確認",N30="確認"),O30<>"不要"),Z30,0) -> 0 | AF30: =IF(AE30="OK",IF(AC30<>"",AC30,AA30),"") | AO30: =IF(AN30="OK",IF(AL30<>"",AL30,AJ30),"")
B31: =IF(AND(C31<>"",C30<>C31),MAX($B$13:B30)+1,"") | G31: =IF(AND(C30<>C31,C31<>""),IF(SUMIFS($Q$13:$Q$82,$C$13:$C$82,$C31)>=1,1,0),"") | H31: =IF($G31=1,IF(MIN(OFFSET($AA31,0,0,COUNTIF($C31:$C$82,$C31),1))=0,"",MIN(OFFSET($AA31,0,0,COUNTIF($C31:$C$82,$C31),1))),"") | I31: =IF($G31=1,IF(SUMPRODUCT(MAX(($C$13:$C$82=$C31)*($K$13:$K$82)))=COUNTIF($C31:$C$82,C31)-COUNTBLANK(OFFSET($AF31,0,0,COUNTIF($C31:$C$82,$C31),1)),IF(MAX(OFFSET($AF31,0,0,COUNTIF($C31:$C$82,$C31),1))=0,"",MAX(OFFSET($AF31,0,0,COUNTIF($C31:$C$82,$C31),1))),""),"") | J31: =IF(C31=0,"",IF(C30=C31,SUMPRODUCT(MAX(($C$11:$C30=C31)*($J$11:$J30))+1),1)) | K31: =IF(C31=0,0,IF(AND(OR(N31="入力・確認",N31="確認"),O31<>"不要"),IF(C30=C31,SUMPRODUCT(MAX(($C$12:$C30=C31)*($K$12:$K30))+1),1),0)) -> 0 | Q31: =IF(AND(OR(N31="入力・確認",N31="確認"),O31<>"不要"),Z31,0) -> 0 | AF31: =IF(AE31="OK",IF(AC31<>"",AC31,AA31),"") | AO31: =IF(AN31="OK",IF(AL31<>"",AL31,AJ31),"")
B32: =IF(AND(C32<>"",C31<>C32),MAX($B$13:B31)+1,"") | G32: =IF(AND(C31<>C32,C32<>""),IF(SUMIFS($Q$13:$Q$82,$C$13:$C$82,$C32)>=1,1,0),"") | H32: =IF($G32=1,IF(MIN(OFFSET($AA32,0,0,COUNTIF($C32:$C$82,$C32),1))=0,"",MIN(OFFSET($AA32,0,0,COUNTIF($C32:$C$82,$C32),1))),"") | I32: =IF($G32=1,IF(SUMPRODUCT(MAX(($C$13:$C$82=$C32)*($K$13:$K$82)))=COUNTIF($C32:$C$82,C32)-COUNTBLANK(OFFSET($AF32,0,0,COUNTIF($C32:$C$82,$C32),1)),IF(MAX(OFFSET($AF32,0,0,COUNTIF($C32:$C$82,$C32),1))=0,"",MAX(OFFSET($AF32,0,0,COUNTIF($C32:$C$82,$C32),1))),""),"") | J32: =IF(C32=0,"",IF(C31=C32,SUMPRODUCT(MAX(($C$11:$C31=C32)*($J$11:$J31))+1),1)) | K32: =IF(C32=0,0,IF(AND(OR(N32="入力・確認",N32="確認"),O32<>"不要"),IF(C31=C32,SUMPRODUCT(MAX(($C$12:$C31=C32)*($K$12:$K31))+1),1),0)) -> 0 | Q32: =IF(AND(OR(N32="入力・確認",N32="確認"),O32<>"不要"),Z32,0) -> 0 | AF32: =IF(AE32="OK",IF(AC32<>"",AC32,AA32),"") | AO32: =IF(AN32="OK",IF(AL32<>"",AL32,AJ32),"")
B33: =IF(AND(C33<>"",C32<>C33),MAX($B$13:B32)+1,"") | G33: =IF(AND(C32<>C33,C33<>""),IF(SUMIFS($Q$13:$Q$82,$C$13:$C$82,$C33)>=1,1,0),"") | H33: =IF($G33=1,IF(MIN(OFFSET($AA33,0,0,COUNTIF($C33:$C$82,$C33),1))=0,"",MIN(OFFSET($AA33,0,0,COUNTIF($C33:$C$82,$C33),1))),"") | I33: =IF($G33=1,IF(SUMPRODUCT(MAX(($C$13:$C$82=$C33)*($K$13:$K$82)))=COUNTIF($C33:$C$82,C33)-COUNTBLANK(OFFSET($AF33,0,0,COUNTIF($C33:$C$82,$C33),1)),IF(MAX(OFFSET($AF33,0,0,COUNTIF($C33:$C$82,$C33),1))=0,"",MAX(OFFSET($AF33,0,0,COUNTIF($C33:$C$82,$C33),1))),""),"") | J33: =IF(C33=0,"",IF(C32=C33,SUMPRODUCT(MAX(($C$11:$C32=C33)*($J$11:$J32))+1),1)) | K33: =IF(C33=0,0,IF(AND(OR(N33="入力・確認",N33="確認"),O33<>"不要"),IF(C32=C33,SUMPRODUCT(MAX(($C$12:$C32=C33)*($K$12:$K32))+1),1),0)) -> 0 | Q33: =IF(AND(OR(N33="入力・確認",N33="確認"),O33<>"不要"),Z33,0) -> 0 | AF33: =IF(AE33="OK",IF(AC33<>"",AC33,AA33),"") | AO33: =IF(AN33="OK",IF(AL33<>"",AL33,AJ33),"")
B34: =IF(AND(C34<>"",C33<>C34),MAX($B$13:B33)+1,"") | G34: =IF(AND(C33<>C34,C34<>""),IF(SUMIFS($Q$13:$Q$82,$C$13:$C$82,$C34)>=1,1,0),"") | H34: =IF($G34=1,IF(MIN(OFFSET($AA34,0,0,COUNTIF($C34:$C$82,$C34),1))=0,"",MIN(OFFSET($AA34,0,0,COUNTIF($C34:$C$82,$C34),1))),"") | I34: =IF($G34=1,IF(SUMPRODUCT(MAX(($C$13:$C$82=$C34)*($K$13:$K$82)))=COUNTIF($C34:$C$82,C34)-COUNTBLANK(OFFSET($AF34,0,0,COUNTIF($C34:$C$82,$C34),1)),IF(MAX(OFFSET($AF34,0,0,COUNTIF($C34:$C$82,$C34),1))=0,"",MAX(OFFSET($AF34,0,0,COUNTIF($C34:$C$82,$C34),1))),""),"") | J34: =IF(C34=0,"",IF(C33=C34,SUMPRODUCT(MAX(($C$11:$C33=C34)*($J$11:$J33))+1),1)) | K34: =IF(C34=0,0,IF(AND(OR(N34="入力・確認",N34="確認"),O34<>"不要"),IF(C33=C34,SUMPRODUCT(MAX(($C$12:$C33=C34)*($K$12:$K33))+1),1),0)) -> 0 | Q34: =IF(AND(OR(N34="入力・確認",N34="確認"),O34<>"不要"),Z34,0) -> 0 | AF34: =IF(AE34="OK",IF(AC34<>"",AC34,AA34),"") | AO34: =IF(AN34="OK",IF(AL34<>"",AL34,AJ34),"")
B35: =IF(AND(C35<>"",C34<>C35),MAX($B$13:B34)+1,"") | G35: =IF(AND(C34<>C35,C35<>""),IF(SUMIFS($Q$13:$Q$82,$C$13:$C$82,$C35)>=1,1,0),"") | H35: =IF($G35=1,IF(MIN(OFFSET($AA35,0,0,COUNTIF($C35:$C$82,$C35),1))=0,"",MIN(OFFSET($AA35,0,0,COUNTIF($C35:$C$82,$C35),1))),"") | I35: =IF($G35=1,IF(SUMPRODUCT(MAX(($C$13:$C$82=$C35)*($K$13:$K$82)))=COUNTIF($C35:$C$82,C35)-COUNTBLANK(OFFSET($AF35,0,0,COUNTIF($C35:$C$82,$C35),1)),IF(MAX(OFFSET($AF35,0,0,COUNTIF($C35:$C$82,$C35),1))=0,"",MAX(OFFSET($AF35,0,0,COUNTIF($C35:$C$82,$C35),1))),""),"") | J35: =IF(C35=0,"",IF(C34=C35,SUMPRODUCT(MAX(($C$11:$C34=C35)*($J$11:$J34))+1),1)) | K35: =IF(C35=0,0,IF(AND(OR(N35="入力・確認",N35="確認"),O35<>"不要"),IF(C34=C35,SUMPRODUCT(MAX(($C$12:$C34=C35)*($K$12:$K34))+1),1),0)) -> 0 | Q35: =IF(AND(OR(N35="入力・確認",N35="確認"),O35<>"不要"),Z35,0) -> 0 | AF35: =IF(AE35="OK",IF(AC35<>"",AC35,AA35),"") | AO35: =IF(AN35="OK",IF(AL35<>"",AL35,AJ35),"")
B36: =IF(AND(C36<>"",C35<>C36),MAX($B$13:B35)+1,"") | G36: =IF(AND(C35<>C36,C36<>""),IF(SUMIFS($Q$13:$Q$82,$C$13:$C$82,$C36)>=1,1,0),"") | H36: =IF($G36=1,IF(MIN(OFFSET($AA36,0,0,COUNTIF($C36:$C$82,$C36),1))=0,"",MIN(OFFSET($AA36,0,0,COUNTIF($C36:$C$82,$C36),1))),"") | I36: =IF($G36=1,IF(SUMPRODUCT(MAX(($C$13:$C$82=$C36)*($K$13:$K$82)))=COUNTIF($C36:$C$82,C36)-COUNTBLANK(OFFSET($AF36,0,0,COUNTIF($C36:$C$82,$C36),1)),IF(MAX(OFFSET($AF36,0,0,COUNTIF($C36:$C$82,$C36),1))=0,"",MAX(OFFSET($AF36,0,0,COUNTIF($C36:$C$82,$C36),1))),""),"") | J36: =IF(C36=0,"",IF(C35=C36,SUMPRODUCT(MAX(($C$11:$C35=C36)*($J$11:$J35))+1),1)) | K36: =IF(C36=0,0,IF(AND(OR(N36="入力・確認",N36="確認"),O36<>"不要"),IF(C35=C36,SUMPRODUCT(MAX(($C$12:$C35=C36)*($K$12:$K35))+1),1),0)) -> 0 | Q36: =IF(AND(OR(N36="入力・確認",N36="確認"),O36<>"不要"),Z36,0) -> 0 | AF36: =IF(AE36="OK",IF(AC36<>"",AC36,AA36),"") | AO36: =IF(AN36="OK",IF(AL36<>"",AL36,AJ36),"")
B37: =IF(AND(C37<>"",C36<>C37),MAX($B$13:B36)+1,"") | G37: =IF(AND(C36<>C37,C37<>""),IF(SUMIFS($Q$13:$Q$82,$C$13:$C$82,$C37)>=1,1,0),"") | H37: =IF($G37=1,IF(MIN(OFFSET($AA37,0,0,COUNTIF($C37:$C$82,$C37),1))=0,"",MIN(OFFSET($AA37,0,0,COUNTIF($C37:$C$82,$C37),1))),"") | I37: =IF($G37=1,IF(SUMPRODUCT(MAX(($C$13:$C$82=$C37)*($K$13:$K$82)))=COUNTIF($C37:$C$82,C37)-COUNTBLANK(OFFSET($AF37,0,0,COUNTIF($C37:$C$82,$C37),1)),IF(MAX(OFFSET($AF37,0,0,COUNTIF($C37:$C$82,$C37),1))=0,"",MAX(OFFSET($AF37,0,0,COUNTIF($C37:$C$82,$C37),1))),""),"") | J37: =IF(C37=0,"",IF(C36=C37,SUMPRODUCT(MAX(($C$11:$C36=C37)*($J$11:$J36))+1),1)) | K37: =IF(C37=0,0,IF(AND(OR(N37="入力・確認",N37="確認"),O37<>"不要"),IF(C36=C37,SUMPRODUCT(MAX(($C$12:$C36=C37)*($K$12:$K36))+1),1),0)) -> 0 | Q37: =IF(AND(OR(N37="入力・確認",N37="確認"),O37<>"不要"),Z37,0) -> 0 | AF37: =IF(AE37="OK",IF(AC37<>"",AC37,AA37),"") | AO37: =IF(AN37="OK",IF(AL37<>"",AL37,AJ37),"")
B38: =IF(AND(C38<>"",C37<>C38),MAX($B$13:B37)+1,"") | G38: =IF(AND(C37<>C38,C38<>""),IF(SUMIFS($Q$13:$Q$82,$C$13:$C$82,$C38)>=1,1,0),"") | H38: =IF($G38=1,IF(MIN(OFFSET($AA38,0,0,COUNTIF($C38:$C$82,$C38),1))=0,"",MIN(OFFSET($AA38,0,0,COUNTIF($C38:$C$82,$C38),1))),"") | I38: =IF($G38=1,IF(SUMPRODUCT(MAX(($C$13:$C$82=$C38)*($K$13:$K$82)))=COUNTIF($C38:$C$82,C38)-COUNTBLANK(OFFSET($AF38,0,0,COUNTIF($C38:$C$82,$C38),1)),IF(MAX(OFFSET($AF38,0,0,COUNTIF($C38:$C$82,$C38),1))=0,"",MAX(OFFSET($AF38,0,0,COUNTIF($C38:$C$82,$C38),1))),""),"") | J38: =IF(C38=0,"",IF(C37=C38,SUMPRODUCT(MAX(($C$11:$C37=C38)*($J$11:$J37))+1),1)) | K38: =IF(C38=0,0,IF(AND(OR(N38="入力・確認",N38="確認"),O38<>"不要"),IF(C37=C38,SUMPRODUCT(MAX(($C$12:$C37=C38)*($K$12:$K37))+1),1),0)) -> 0 | Q38: =IF(AND(OR(N38="入力・確認",N38="確認"),O38<>"不要"),Z38,0) -> 0 | AF38: =IF(AE38="OK",IF(AC38<>"",AC38,AA38),"") | AO38: =IF(AN38="OK",IF(AL38<>"",AL38,AJ38),"")
B39: =IF(AND(C39<>"",C38<>C39),MAX($B$13:B38)+1,"") | G39: =IF(AND(C38<>C39,C39<>""),IF(SUMIFS($Q$13:$Q$82,$C$13:$C$82,$C39)>=1,1,0),"") | H39: =IF($G39=1,IF(MIN(OFFSET($AA39,0,0,COUNTIF($C39:$C$82,$C39),1))=0,"",MIN(OFFSET($AA39,0,0,COUNTIF($C39:$C$82,$C39),1))),"") | I39: =IF($G39=1,IF(SUMPRODUCT(MAX(($C$13:$C$82=$C39)*($K$13:$K$82)))=COUNTIF($C39:$C$82,C39)-COUNTBLANK(OFFSET($AF39,0,0,COUNTIF($C39:$C$82,$C39),1)),IF(MAX(OFFSET($AF39,0,0,COUNTIF($C39:$C$82,$C39),1))=0,"",MAX(OFFSET($AF39,0,0,COUNTIF($C39:$C$82,$C39),1))),""),"") | J39: =IF(C39=0,"",IF(C38=C39,SUMPRODUCT(MAX(($C$11:$C38=C39)*($J$11:$J38))+1),1)) | K39: =IF(C39=0,0,IF(AND(OR(N39="入力・確認",N39="確認"),O39<>"不要"),IF(C38=C39,SUMPRODUCT(MAX(($C$12:$C38=C39)*($K$12:$K38))+1),1),0)) -> 0 | Q39: =IF(AND(OR(N39="入力・確認",N39="確認"),O39<>"不要"),Z39,0) -> 0 | AF39: =IF(AE39="OK",IF(AC39<>"",AC39,AA39),"") | AO39: =IF(AN39="OK",IF(AL39<>"",AL39,AJ39),"")
... B81: =IF(AND(C81<>"",C80<>C81),MAX($B$13:B80)+1,"") | G81: =IF(AND(C80<>C81,C81<>""),IF(SUMIFS($Q$13:$Q$82,$C$13:$C$82,$C81)>=1,1,0),"") | H81: =IF($G81=1,IF(MIN(OFFSET($AA81,0,0,COUNTIF($C81:$C$82,$C81),1))=0,"",MIN(OFFSET($AA81,0,0,COUNTIF($C81:$C$82,$C81),1))),"") | I81: =IF($G81=1,IF(SUMPRODUCT(MAX(($C$13:$C$82=$C81)*($K$13:$K$82)))=COUNTIF($C81:$C$82,C81)-COUNTBLANK(OFFSET($AF81,0,0,COUNTIF($C81:$C$82,$C81),1)),IF(MAX(OFFSET($AF81,0,0,COUNTIF($C81:$C$82,$C81),1))=0,"",MAX(OFFSET($AF81,0,0,COUNTIF($C81:$C$82,$C81),1))),""),"") | J81: =IF(C81=0,"",IF(C80=C81,SUMPRODUCT(MAX(($C$11:$C80=C81)*($J$11:$J80))+1),1)) | K81: =IF(C81=0,0,IF(AND(OR(N81="入力・確認",N81="確認"),O81<>"不要"),IF(C80=C81,SUMPRODUCT(MAX(($C$12:$C80=C81)*($K$12:$K80))+1),1),0)) -> 0 | Q81: =IF(AND(OR(N81="入力・確認",N81="確認"),O81<>"不要"),Z81,0) -> 0 | AF81: =IF(AE81="OK",IF(AC81<>"",AC81,AA81),"") | AO81: =IF(AN81="OK",IF(AL81<>"",AL81,AJ81),"")
...

Sheet 対象データ取得
A1: 試験対象データ取得方法
A3: ①TC_NE_OPS_CHECK_KNR（Ne-OpS名チェック管理）登録内容取得
A4: select * from TC_NE_OPS_CHECK_KNR
A6: BPN_CD | B6: MKR_CD | C6: BPN_CD_SUB_NO | D6: SYY_ITI_DAN_NO | E6: SYY_ITI_RET_NO | F6: MK_DDTI | G6: FIN_UDTE_DDTI | H6: UDTE_CONT | I6: FIN_UDTE_USER_CD
A7: 5L530011 | B7: 402 | C7: 1 | D7: 21 | E7: 1 | F7: 44340.52 | G7: 44340.52 | H7: 0 | I7: 2021A
A8: 5L530011 | B8: 402 | C8: 1 | D8: 24 | E8: 1 | F8: 44340.52 | G8: 44340.52 | H8: 0 | I8: 2021A
A9: 5L530011 | B9: 402 | C9: 1 | D9: 27 | E9: 1 | F9: 44340.52 | G9: 44340.52 | H9: 0 | I9: 2021A
A10: 5L530011 | B10: 402 | C10: 1 | D10: 30 | E10: 1 | F10: 44340.52 | G10: 44340.52 | H10: 0 | I10: 2021A
A11: 5L530001 | B11: 402 | C11: 1 | D11: 1 | E11: 1 | F11: 44340.52 | G11: 44340.52 | H11: 0 | I11: 2021A
A12: 5L530003 | B12: 402 | C12: 1 | D12: 1 | E12: 1 | F12: 44340.524 | G12: 44340.524 | H12: 0 | I12: 2021A
A13: 5L530065 | B13: 402 | C13: 1 | D13: 10 | E13: 999 | F13: 44340.524 | G13: 44340.524 | H13: 0 | I13: 2021A
A14: 5L530065 | B14: 402 | C14: 1 | D14: 20 | E14: 999 | F14: 44340.524 | G14: 44340.524 | H14: 0 | I14: 2021A
A15: 5L530065 | B15: 402 | C15: 1 | D15: 30 | E15: 999 | F15: 44340.524 | G15: 44340.524 | H15: 0 | I15: 2021A
A16: 5L530065 | B16: 402 | C16: 1 | D16: 40 | E16: 999 | F16: 44340.524 | G16: 44340.524 | H16: 0 | I16: 2021A
A17: 5L530065 | B17: 402 | C17: 1 | D17: 50 | E17: 999 | F17: 44340.524 | G17: 44340.524 | H17: 0 | I17: 2021A
A18: 5L530065 | B18: 402 | C18: 1 | D18: 60 | E18: 999 | F18: 44340.524 | G18: 44340.524 | H18: 0 | I18: 2021A
... A21: 5L530071 | B21: 402 | C21: 1 | D21: 1 | E21: 1 | F21: 44607.681 | G21: 44607.681 | H21: 0 | I21: L1SMK-830
A24: ②上記取得結果から１件選び（どれでもよい）、TD_SOTI_SYY_KIKIでレコードを検索する
A25: （今回は１３行目のレコードを使用）
A26: select * from TD_SOTI_SYY_KIKI where BPN_CD = '5L530065' and MKR_CD = '402' and BPN_CD_SUB_NO = '1' and SYY_ITI_DAN_NO = '10' and SYY_ITI_RET_NO = '999'
A28: KIKI_ID | B28: UPPR_KIKI_ID | C28: BLDG_CD | D28: FLOR_CD | E28: GN_CD | F28: GA_NO | G28: SYY_ITI_URA_KBN | H28: SYY_ITI_DAN_NO | I28: SYY_ITI_RET_NO | J28: SYY_ITI_MSAI_NO | K28: SYY_ITI_NAM | L28: SYY_ITI_DAN_RZKSU | M28: SYY_ITI_RET_RZKSU | N28: YHIN_KBN | O28: BPN_CD | P28: MKR_CD | Q28: BPN_CD_SUB_NO | R28: SEZO_YYMM | S28: RIYO_KBN | T28: SSN_KBN | U28: KMKM_SBAY_KBN | V28: SOTI_STTS_KBN | W28: CLS_SYRI_KBN | X28: KM_FLG | Y28: OYA_KIKI_ID | Z28: KOJI_PLAN_NO | AA28: DNGN_SBT1 | AB28: DNGN_SBT2 | AC28: DNGN_SBT3 | AD28: MAX_DNRY1 | AE28: MAX_DNRY2 | AF28: MAX_DNRY3 | AG28: KYKU_DNGN_SBT | AH28: KYYO_DNRY | AI28: UNT_FITAS_KBN | AJ28: UNT_SOSA_NO | AK28: PNL_TNS_ITI | AL28: PNL_SEC_CD | AM28: YTO | AN28: MK_DDTI | AO28: FIN_UDTE_DDTI | AP28: UDTE_CONT | AQ28: FIN_UDTE_USER_CD | AR28: IP_ADDR | AS28: TID | AT28: NE_OPS_NAME | AU28: SOTI_ATT1 | AV28: SOTI_ATT2 | AW28: SOTI_ATT3 | AX28: SOTI_ATT4 | AY28: SOTI_ATT5 | AZ28: IP_ADDR2 | BA28: SUBNET_ADDR | BB28: GW_ADDR | BC28: BPN_YTO | BD28: JGSY_KBN | BE28: AREAMN1 | BF28: AREAMN2
A29: 0728629242 | B29: 0 | C29: 1310611001 | D29: 007 | E29: N | F29: 5002 | G29: 0 | H29: 10 | I29: 999 | J29: 10 | K29: TEST | L29: « NULL » | M29: « NULL » | N29: 7 | O29: 5L530065 | P29: 402 | Q29: 1 | R29: « NULL » | S29: 01 | T29: 10 | U29: 4 | V29: 1 | X29: 0 | Y29: « NULL » | Z29: « NULL » | AA29: « NULL » | AB29: « NULL » | AC29: « NULL » | AD29: « NULL » | AE29: « NULL » | AF29: « NULL » | AG29: « NULL » | AH29: « NULL » | AJ29: « NULL » | AK29: « NULL » | AL29: « NULL » | AM29: « NULL » | AN29: 44418.576 | AO29: 45189.418 | AP29: 4 | AQ29: DevA021 | AR29: « NULL » | AS29: « NULL » | AT29: sirahige007E025002SW10 | AU29: « NULL » | AV29: « NULL » | AW29: « NULL » | AX29: « NULL » | AY29: « NULL » | AZ29: « NULL » | BA29: « NULL » | BB29: « NULL » | BC29: « NULL » | BD29: 02 | BE29: « NULL » | BF29: « NULL »
A30: 0728646960 | B30: 0 | C30: 4120100301 | D30: 002 | E30: N | F30: 13 | G30: 0 | H30: 10 | I30: 999 | J30: 10 | K30: TEST | L30: « NULL » | M30: « NULL » | N30: 7 | O30: 5L530065 | P30: 402 | Q30: 1 | R30: « NULL » | S30: 01 | T30: 10 | U30: 4 | V30: 1 | X30: 0 | Y30: « NULL » | Z30: « NULL » | AA30: « NULL » | AB30: « NULL » | AC30: « NULL » | AD30: « NULL » | AE30: « NULL » | AF30: « NULL » | AG30: « NULL » | AH30: « NULL » | AJ30: « NULL » | AK30: « NULL » | AL30: « NULL » | AM30: « NULL » | AN30: 44806.127 | AO30: 45496.698 | AP30: 1 | AQ30: CDDB0100 | AR30: « NULL » | AS30: « NULL » | AT30: takagise002D020013SW10 | AU30: « NULL » | AV30: « NULL » | AW30: « NULL » | AX30: « NULL » | AY30: « NULL » | AZ30: « NULL » | BA30: « NULL » | BB30: « NULL » | BC30: « NULL » | BD30: « NULL » | BE30: « NULL » | BF30: « NULL »
A31: 0728624559 | B31: 0 | C31: 0220110501 | D31: 001 | E31: N | F31: 9011 | G31: 0 | H31: 10 | I31: 999 | J31: 10 | K31: U32 | L31: « NULL » | M31: « NULL » | N31: 7 | O31: 5L530065 | P31: 402 | Q31: 1 | R31: « NULL » | S31: 01 | T31: 10 | U31: 4 | V31: 6 | X31: 0 | Y31: « NULL » | Z31: « NULL » | AA31: « NULL » | AB31: « NULL » | AC31: « NULL » | AD31: « NULL » | AE31: « NULL » | AF31: « NULL » | AG31: « NULL » | AH31: « NULL » | AJ31: « NULL » | AK31: « NULL » | AL31: « NULL » | AM31: « NULL » | AN31: 44308.642 | AO31: 44343.496 | AP31: 1 | AQ31: autoTest | AR31: « NULL » | AS31: « NULL » | AT31: aomori2001TES9011SW10 | AU31: « NULL » | AV31: « NULL » | AW31: « NULL » | AX31: « NULL » | AY31: « NULL » | AZ31: « NULL » | BA31: « NULL » | BB31: « NULL » | BC31: « NULL » | BD31: 01 | BE31: « NULL » | BF31: « NULL »
A32: 0728625577 | B32: 0 | C32: 1310611001 | D32: 007 | E32: N | F32: 5001 | G32: 0 | H32: 10 | I32: 999 | J32: 10 | K32: TEST01 | L32: « NULL » | M32: « NULL » | N32: 7 | O32: 5L530065 | P32: 402 | Q32: 1 | R32: « NULL » | S32: 01 | T32: 10 | U32: 4 | V32: 6 | X32: 0 | Y32: « NULL » | Z32: « NULL » | AA32: « NULL » | AB32: « NULL » | AC32: « NULL » | AD32: « NULL » | AE32: « NULL » | AF32: « NULL » | AG32: « NULL » | AH32: « NULL » | AJ32: « NULL » | AK32: « NULL » | AL32: « NULL » | AM32: « NULL » | AN32: 44330.624 | AO32: 45190.615 | AP32: 3 | AQ32: DevA053 | AR32: « NULL » | AS32: « NULL » | AT32: sirahige007E025001SW10 | AU32: « NULL » | AV32: « NULL » | AW32: « NULL » | AX32: « NULL » | AY32: « NULL » | AZ32: « NULL » | BA32: « NULL » | BB32: « NULL » | BC32: « NULL » | BD32: 01 | BE32: « NULL » | BF32: « NULL »
A33: 0728626358 | B33: 0 | C33: 1410300101 | D33: 006 | E33: N | F33: 5001 | G33: 0 | H33: 10 | I33: 999 | J33: 10 | K33: TEST01 | L33: « NULL » | M33: « NULL » | N33: 7 | O33: 5L530065 | P33: 402 | Q33: 1 | R33: « NULL » | S33: 01 | T33: 12 | U33: 4 | V33: 6 | X33: 0 | Y33: « NULL » | Z33: « NULL » | AA33: « NULL » | AB33: « NULL » | AC33: « NULL » | AD33: « NULL » | AE33: « NULL » | AF33: « NULL » | AG33: « NULL » | AH33: « NULL » | AJ33: « NULL » | AK33: « NULL » | AL33: « NULL » | AM33: « NULL » | AN33: 44340.391 | AO33: 44340.88 | AP33: 1 | AQ33: CDDB0100 | AR33: « NULL » | AS33: « NULL » | AT33: yokonisi006J095001SW10 | AU33: « NULL » | AV33: « NULL » | AW33: « NULL » | AX33: « NULL » | AY33: « NULL » | AZ33: « NULL » | BA33: « NULL » | BB33: « NULL » | BC33: « NULL » | BD33: 01 | BE33: « NULL » | BF33: « NULL »
A36: ③上記②の取得結果から１件選び、TD_NE_OPS_CHECK_ELOG（Ne-OpS名チェックエラーログ）で検索結果が0件になることを確認する
A37: （今回は３０行目のレコードを使用）
A38: select * from td_ne_ops_check_elog where KIKI_ID = '0728646960';
A41: ④上記②で選択したレコードのビル、フロア、群、架、ユニット物品コードを、確認用シートのD3～D7に記載する

Sheet 実施手順
B1: 0．事前準備
B3: ① | C3: A5M2で習熟L1DBに接続
B5: ② | C5: select * FROM TD_KOMA_MNG;
C6: ⇒ | D6: 出力された結果を別途保存しておく
B8: ③ | C8: select COUNT(*) FROM TD_KOMA_MNG;
C9: ⇒ | D9: 出力された結果を別途保存しておく
B11: ※②③が存在しない場合、バッチを実行しても処理対象が存在しない可能性あり
B13: ④ | C13: TeraTermでl1ds-comtrn-l1batch-bat01に接続
C14: RAGW | F14: 10.39.37.133
C15: 踏み台 | F15: 10.223.153.201 | J15: l1ds-comtrn-l1batch-bat02
C16: IPアドレス | F16: 10.223.153.200 | J16: l1ds-comtrn-l1batch-bat01
C17: ユーザ名 | F17: l1db01
B19: ⑤ | C19: プロセス確認
C20: ps ef | grep CDDB2000.sh
C21: ⇒ | D21: プロセスが存在しない(起動していない)場合は⑥および「１．バッチ実行」を実施
D22: ※業務上意図的に止められている可能性もあるため、リーダーに確認すること
B24: ⑥ | C24: 以下コマンド実行し、envファイルの中身を確認
B25: $ | C25: less /home/l1db/jsvc/l1batch/CDDB2000/bin/CDDB2000.env
C26: ⇒STOP=startであること
C27: ※STOP=stopである場合、書き換えする
C46: 確認後は以下コマンドでファイル閲覧状態から抜け出す
C47: 「esc」＋「：」＋「ｑ」
B49: 1．バッチ実行
B51: ① | C51: バッチ実行前に日付を抑えておく
B54: ② | C54: shコマンド実行
B55: $ | C55: sh -vx /home/l1db/jsvc/l1batch/CDDB2000/bin/CDDB2000.sh
C56: 以下画像のようなlogが出力されたら、「ctrl + C」を押下
B82: 2．結果確認
B84: ① | C84: A5M2で習熟L1DBに接続
B86: ② | C86: select * from TD_SOTI_SYY_KIKI where BPN_CD = '5L530065' and MKR_CD = '402' and BPN_CD_SUB_NO = '1' and SYY_ITI_DAN_NO = '10' and SYY_ITI_RET_NO = '999'
C87: 「NE_OPS_NAME」を確認
C88: ⇒ | D88: 正しい値が入っていること
B90: ③ | C90: TeraTermでl1ds-comtrn-l1batch-bat01に接続
C91: RAGW | F91: 10.39.37.133
C92: 踏み台 | F92: 10.223.153.201 | J92: l1ds-comtrn-l1batch-bat02
C93: IPアドレス | F93: 10.223.153.200 | J93: l1ds-comtrn-l1batch-bat01
C94: ユーザ名 | F94: l1db01
B96: ④ | C96: ログを確認する
C97: ・JOBLOG
D98: less /home/l1db/log/bat/JOBLOG.log
...

Sheet 確認用
A2: テストケース | B2: 操作 | C2: 入力値、SQL等
A3: IT-001 | B3: NWZC7600検索条件 | C3: ビルコード | D3: 4120100301
C4: フロア | D4: 002
C5: 群 | D5: N
C6: 架番号 | D6: 13
C7: ﾕﾆｯﾄ物品ｺｰﾄﾞ | D7: 5L530065
B8: 装置収容機器確認 | C8: ="select * from td_soti_syy_kiki where bldg_cd = '"&$D$3&"' and flor_cd = '"&$D$4&"' and gn_cd = '"&$D$5&"' and ga_no = '"&$D$6&"' and bpn_cd = '"&$D$7&"';" -> select * from td_soti_syy_kiki where bldg_cd = '4120100301' and flor_cd = '002' and gn_cd = 'N' and ga_no = '13' and bpn_cd = '5L530065';
B9: コマ名変更データパッチ | C9: ="update td_ga set komanam = 'NG' where bldg_cd = '"&$D$3&"' and flor_cd = '"&$D$4&"' and gn_cd = '"&$D$5&"' and ga_no = '"&$D$6&"';" -> update td_ga set komanam = 'NG' where bldg_cd = '4120100301' and flor_cd = '002' and gn_cd = 'N' and ga_no = '13';
B10: コマ名修正データパッチ | C10: ="update td_ga set komanam = 'D02' where bldg_cd ='"&$D$3&"' and flor_cd ='"&$D$4&"'and gn_cd = '"&$D$5&"' and ga_no = '"&$D$6&"';" -> update td_ga set komanam = 'D02' where bldg_cd ='4120100301' and flor_cd ='002'and gn_cd = 'N' and ga_no = '13';

Sheet ディシジョン表
D2: 実施テストケース | E2: =IFERROR(IF(E3="","",INDEX(試験項目書!$C$12:$C$82,MATCH(E3,試験項目書!$V$12:$V$82,0))),"") | F2: =IFERROR(IF(F3="","",INDEX(試験項目書!$C$12:$C$82,MATCH(F3,試験項目書!$V$12:$V$82,0))),"") | G2: =IFERROR(IF(G3="","",INDEX(試験項目書!$C$12:$C$82,MATCH(G3,試験項目書!$V$12:$V$82,0))),"") | H2: =IFERROR(IF(H3="","",INDEX(試験項目書!$C$12:$C$82,MATCH(H3,試験項目書!$V$12:$V$82,0))),"") | I2: =IFERROR(IF(I3="","",INDEX(試験項目書!$C$12:$C$82,MATCH(I3,試験項目書!$V$12:$V$82,0))),"") | J2: =IFERROR(IF(J3="","",INDEX(試験項目書!$C$12:$C$82,MATCH(J3,試験項目書!$V$12:$V$82,0))),"") | K2: =IFERROR(IF(K3="","",INDEX(試験項目書!$C$12:$C$82,MATCH(K3,試験項目書!$V$12:$V$82,0))),"") | L2: =IFERROR(IF(L3="","",INDEX(試験項目書!$C$12:$C$82,MATCH(L3,試験項目書!$V$12:$V$82,0))),"") | ... X2: =IFERROR(IF(X3="","",INDEX(試験項目書!$C$12:$C$82,MATCH(X3,試験項目書!$V$12:$V$82,0))),"")
B3: 条件概要 | C3: 条件 | D3: データ例 | E3: DT100-001 | F3: DT100-002 | G3: DT100-003 | H3: DT100-004 | I3: DT100-005 | J3: DT100-006 | K3: DT100-007 | L3: DT100-008 | M3: DT100-009 | N3: DT100-010 | O3: DT100-011 | P3: DT100-012 | Q3: DT100-013 | R3: DT100-014 | S3: DT100-015 | T3: DT100-016 | U3: DT100-017 | V3: DT100-018 | W3: DT100-019 | X3: DT100-020
B4: 割引率条件 | C4: 雨の日 | E4: Y | F4: N | G4: N | H4: N
C5: 平日 | E5: ― | F5: Y | G5: N | H5: N
C6: クーポン持参 | E6: ― | F6: ― | G6: Y | H6: N
B7: 期待値（適用） | C7: 期待値（適用） | D7: 補足
B8: 適用割引率 | C8: 割引なし | H8: Y | Y8: EOL
C9: 5％OFF | G9: Y | Y9: EOL
C10: 10％OFF | F10: Y | Y10: EOL
C11: 20％OFF | E11: Y | Y11: EOL
B12: EOL | C12: EOL | D12: EOL | E12: EOL | V12: EOL | W12: EOL | X12: EOL
D15: 実施テストケース | E15: =IFERROR(IF(E16="","",INDEX(試験項目書!$C$12:$C$82,MATCH(E16,試験項目書!$V$12:$V$82,0))),"") | F15: =IFERROR(IF(F16="","",INDEX(試験項目書!$C$12:$C$82,MATCH(F16,試験項目書!$V$12:$V$82,0))),"") | G15: =IFERROR(IF(G16="","",INDEX(試験項目書!$C$12:$C$82,MATCH(G16,試験項目書!$V$12:$V$82,0))),"") | H15: =IFERROR(IF(H16="","",INDEX(試験項目書!$C$12:$C$82,MATCH(H16,試験項目書!$V$12:$V$82,0))),"") | I15: =IFERROR(IF(I16="","",INDEX(試験項目書!$C$12:$C$82,MATCH(I16,試験項目書!$V$12:$V$82,0))),"") | J15: =IFERROR(IF(J16="","",INDEX(試験項目書!$C$12:$C$82,MATCH(J16,試験項目書!$V$12:$V$82,0))),"") | K15: =IFERROR(IF(K16="","",INDEX(試験項目書!$C$12:$C$82,MATCH(K16,試験項目書!$V$12:$V$82,0))),"") | L15: =IFERROR(IF(L16="","",INDEX(試験項目書!$C$12:$C$82,MATCH(L16,試験項目書!$V$12:$V$82,0))),"") | ... X15: =IFERROR(IF(X16="","",INDEX(試験項目書!$C$12:$C$82,MATCH(X16,試験項目書!$V$12:$V$82,0))),"")
B16: 条件概要 | C16: 条件 | D16: データ例 | E16: DT200-001 | F16: DT200-002 | G16: DT200-003 | H16: DT200-004 | I16: DT200-005 | J16: DT200-006 | K16: DT200-007 | L16: DT200-008 | M16: DT200-009 | N16: DT200-010 | O16: DT200-011 | P16: DT200-012 | Q16: DT200-013 | R16: DT200-014 | S16: DT200-015 | T16: DT200-016 | U16: DT200-017 | V16: DT200-018 | W16: DT200-019 | X16: DT200-020
B17: 割引率条件 | C17: 雨の日 | E17: Y | F17: N | G17: N | H17: N
C18: 平日 | E18: ― | F18: Y | G18: N | H18: N
C19: クーポン持参 | E19: ― | F19: ― | G19: Y | H19: N
B20: 期待値（適用） | C20: 期待値（適用） | D20: 補足
B21: 適用割引率 | C21: 割引なし | H21: Y | Y21: EOL
C22: 5％OFF | G22: Y | Y22: EOL
C23: 10％OFF | F23: Y | Y23: EOL
C24: 20％OFF | E24: Y | Y24: EOL
B25: EOL | C25: EOL | D25: EOL | E25: EOL | V25: EOL | W25: EOL | X25: EOL

Sheet 集計
B1: 基準日 | C1: =LEFT(IF(COUNTA(試験項目書!H13:H82)-COUNTBLANK(試験項目書!H13:H82)=0,TEXT(NOW(),"yyyy/mm/dd"),TEXT(MIN(試験項目書!H13:H82),"yyyy/mm/dd")),8)&"01" -> 1900/01/01
B2: 試験ケース数 | C2: =試験項目書!D2 -> 1
B3: 試験項目数 | C3: =試験項目書!D3 -> 8
C5: =C1 -> 1900/01/01 | D5: =C5+1 -> 2 | E5: =D5+1 -> 3 | F5: =E5+1 -> 4 | G5: =F5+1 -> 5 | H5: =G5+1 -> 6 | I5: =H5+1 -> 7 | J5: =I5+1 -> 8 | K5: =J5+1 -> 9 | ... BU5: =BT5+1 -> 71
B6: 実施 | C6: =SUMIFS(試験項目書!$G:$G,試験項目書!$H:$H,集計!C$5) -> 0 | D6: =SUMIFS(試験項目書!$G:$G,試験項目書!$H:$H,集計!D$5) -> 0 | E6: =SUMIFS(試験項目書!$G:$G,試験項目書!$H:$H,集計!E$5) -> 0 | F6: =SUMIFS(試験項目書!$G:$G,試験項目書!$H:$H,集計!F$5) -> 0 | G6: =SUMIFS(試験項目書!$G:$G,試験項目書!$H:$H,集計!G$5) -> 0 | H6: =SUMIFS(試験項目書!$G:$G,試験項目書!$H:$H,集計!H$5) -> 0 | I6: =SUMIFS(試験項目書!$G:$G,試験項目書!$H:$H,集計!I$5) -> 0 | J6: =SUMIFS(試験項目書!$G:$G,試験項目書!$H:$H,集計!J$5) -> 0 | ... BU6: =SUMIFS(試験項目書!$G:$G,試験項目書!$H:$H,集計!BU$5) -> 0
B7: 完了 | C7: =SUMIFS(試験項目書!$G:$G,試験項目書!$I:$I,集計!C$5) -> 0 | D7: =SUMIFS(試験項目書!$G:$G,試験項目書!$I:$I,集計!D$5) -> 0 | E7: =SUMIFS(試験項目書!$G:$G,試験項目書!$I:$I,集計!E$5) -> 0 | F7: =SUMIFS(試験項目書!$G:$G,試験項目書!$I:$I,集計!F$5) -> 0 | G7: =SUMIFS(試験項目書!$G:$G,試験項目書!$I:$I,集計!G$5) -> 0 | H7: =SUMIFS(試験項目書!$G:$G,試験項目書!$I:$I,集計!H$5) -> 0 | I7: =SUMIFS(試験項目書!$G:$G,試験項目書!$I:$I,集計!I$5) -> 0 | J7: =SUMIFS(試験項目書!$G:$G,試験項目書!$I:$I,集計!J$5) -> 0 | ... BU7: =SUMIFS(試験項目書!$G:$G,試験項目書!$I:$I,集計!BU$5) -> 0
B8: 未完了 | C8: =$C$2-C7 -> 1 | D8: =C8-D7 -> 1 | E8: =D8-E7 -> 1 | F8: =E8-F7 -> 1 | G8: =F8-G7 -> 1 | H8: =G8-H7 -> 1 | I8: =H8-I7 -> 1 | J8: =I8-J7 -> 1 | K8: =J8-K7 -> 1 | ... BU8: =BT8-BU7 -> 1
B9: 実施 | C9: =SUMIFS(試験項目書!$Q:$Q,試験項目書!$AA:$AA,集計!C$5) -> 0 | D9: =SUMIFS(試験項目書!$Q:$Q,試験項目書!$AA:$AA,集計!D$5) -> 0 | E9: =SUMIFS(試験項目書!$Q:$Q,試験項目書!$AA:$AA,集計!E$5) -> 0 | F9: =SUMIFS(試験項目書!$Q:$Q,試験項目書!$AA:$AA,集計!F$5) -> 0 | G9: =SUMIFS(試験項目書!$Q:$Q,試験項目書!$AA:$AA,集計!G$5) -> 0 | H9: =SUMIFS(試験項目書!$Q:$Q,試験項目書!$AA:$AA,集計!H$5) -> 0 | I9: =SUMIFS(試験項目書!$Q:$Q,試験項目書!$AA:$AA,集計!I$5) -> 0 | J9: =SUMIFS(試験項目書!$Q:$Q,試験項目書!$AA:$AA,集計!J$5) -> 0 | ... BU9: =SUMIFS(試験項目書!$Q:$Q,試験項目書!$AA:$AA,集計!BU$5) -> 0
B10: 完了 | C10: =SUMIFS(試験項目書!$Q:$Q,試験項目書!$AF:$AF,集計!C$5) -> 0 | D10: =SUMIFS(試験項目書!$Q:$Q,試験項目書!$AF:$AF,集計!D$5) -> 0 | E10: =SUMIFS(試験項目書!$Q:$Q,試験項目書!$AF:$AF,集計!E$5) -> 0 | F10: =SUMIFS(試験項目書!$Q:$Q,試験項目書!$AF:$AF,集計!F$5) -> 0 | G10: =SUMIFS(試験項目書!$Q:$Q,試験項目書!$AF:$AF,集計!G$5) -> 0 | H10: =SUMIFS(試験項目書!$Q:$Q,試験項目書!$AF:$AF,集計!H$5) -> 0 | I10: =SUMIFS(試験項目書!$Q:$Q,試験項目書!$AF:$AF,集計!I$5) -> 0 | J10: =SUMIFS(試験項目書!$Q:$Q,試験項目書!$AF:$AF,集計!J$5) -> 0 | ... BU10: =SUMIFS(試験項目書!$Q:$Q,試験項目書!$AF:$AF,集計!BU$5) -> 0
B11: 未完了 | C11: =$C$3-C10 -> 8 | D11: =C11-D10 -> 8 | E11: =D11-E10 -> 8 | F11: =E11-F10 -> 8 | G11: =F11-G10 -> 8 | H11: =G11-H10 -> 8 | I11: =H11-I10 -> 8 | J11: =I11-J10 -> 8 | K11: =J11-K10 -> 8 | ... BU11: =BT11-BU10 -> 8
B12: 実施 | C12: =SUMIFS(試験項目書!$O:$O,試験項目書!$Y:$Y,集計!C$5) -> 0 | D12: =SUMIFS(試験項目書!$O:$O,試験項目書!$Y:$Y,集計!D$5) -> 0 | E12: =SUMIFS(試験項目書!$O:$O,試験項目書!$Y:$Y,集計!E$5) -> 0 | F12: =SUMIFS(試験項目書!$O:$O,試験項目書!$Y:$Y,集計!F$5) -> 0 | G12: =SUMIFS(試験項目書!$O:$O,試験項目書!$Y:$Y,集計!G$5) -> 0 | H12: =SUMIFS(試験項目書!$O:$O,試験項目書!$Y:$Y,集計!H$5) -> 0 | I12: =SUMIFS(試験項目書!$O:$O,試験項目書!$Y:$Y,集計!I$5) -> 0 | J12: =SUMIFS(試験項目書!$O:$O,試験項目書!$Y:$Y,集計!J$5) -> 0 | ... BU12: =SUMIFS(試験項目書!$O:$O,試験項目書!$Y:$Y,集計!BU$5) -> 0
B13: 完了（クロスチェック） | C13: =SUMIFS(試験項目書!$Q:$Q,試験項目書!$AO:$AO,集計!C$5) -> 0 | D13: =SUMIFS(試験項目書!$Q:$Q,試験項目書!$AO:$AO,集計!D$5) -> 0 | E13: =SUMIFS(試験項目書!$Q:$Q,試験項目書!$AO:$AO,集計!E$5) -> 0 | F13: =SUMIFS(試験項目書!$Q:$Q,試験項目書!$AO:$AO,集計!F$5) -> 0 | G13: =SUMIFS(試験項目書!$Q:$Q,試験項目書!$AO:$AO,集計!G$5) -> 0 | H13: =SUMIFS(試験項目書!$Q:$Q,試験項目書!$AO:$AO,集計!H$5) -> 0 | I13: =SUMIFS(試験項目書!$Q:$Q,試験項目書!$AO:$AO,集計!I$5) -> 0 | J13: =SUMIFS(試験項目書!$Q:$Q,試験項目書!$AO:$AO,集計!J$5) -> 0 | ... BU13: =SUMIFS(試験項目書!$Q:$Q,試験項目書!$AO:$AO,集計!BU$5) -> 0
B14: 未完了 | C14: =$C$3-C13 -> 8 | D14: =$C$3-D13 -> 8 | E14: =$C$3-E13 -> 8 | F14: =$C$3-F13 -> 8 | G14: =$C$3-G13 -> 8 | H14: =$C$3-H13 -> 8 | I14: =$C$3-I13 -> 8 | J14: =$C$3-J13 -> 8 | ... BU14: =$C$3-BU13 -> 8
B16: ※当シートを外部リンクしているので、フォーマット変更しないでください

Sheet マスタ
A1: テストフェーズ | B1: 確認分類
A2: UT_単体テスト | B2: 出力内容確認 | C2: 入力チェック | D2: 画面動作 | E2: 命令網羅（C0） | F2: 分岐網羅（C1） | G2: 条件網羅（最少/最大/異常/境界） | H2: 繰返し（最少/最大/異常/境界） | I2: 演算確認 | J2: メッセージ確認 | K2: エラー確認
A3: IT1_処理結合テスト | B3: 処理確認 | C3: 出力内容確認 | D3: 入力チェック | E3: 画面動作 | F3: 画面遷移 | G3: メッセージ確認 | H3: エラー確認
A4: IT2_機能結合テスト | B4: 機能確認 | C4: 出力内容確認 | D4: 入力チェック | E4: 画面動作 | F4: 画面遷移 | G4: メッセージ確認 | H4: エラー確認
A5: IT3_業務結合テスト | B5: 業務確認 | C5: 出力内容確認 | D5: 入力チェック | E5: 画面動作 | F5: 画面遷移 | G5: メッセージ確認 | H5: エラー確認
A6: IT4_外部連携テスト | B6: 疎通確認 | C6: 機能確認
A7: ST_システムテスト | B7: 業務確認 | C7: 機能確認 | D7: 性能（性能・負荷・ロード） | E7: 拡張性 | F7: 運用・保守性 | G7: 可用性（可用・耐障害・回復） | H7: 移行性 | I7: セキュリティ
A12: EOL | B12: EOL | C12: EOL | D12: EOL | E12: EOL | F12: EOL | G12: EOL | H12: EOL | I12: EOL | J12: EOL | K12: EOL | L12: EOL
A13: 確認機能・確認処理 | B13: 項目分類 | C13: 修正対象
A14: - | B14: 入力 | C14: ○
A15: 画面 | B15: 確認
A16: メッセージ | B16: 入力・確認
A17: DB
A18: ログ
A19: 出力ファイル
B20: EOL | C20: EOL
A144: EOL
